<?xml version='1.0'?>
<sdf version='1.7'>
  <model name='follower_vehicle'>
    <link name='caster'>
      <pose>-0.957138 0 -0.125 0 -0 0</pose>
      <inertial>
        <mass>1</mass>
        <inertia>
          <ixx>0.1</ixx>
          <ixy>0</ixy>
          <ixz>0</ixz>
          <iyy>0.1</iyy>
          <iyz>0</iyz>
          <izz>0.1</izz>
        </inertia>
        <pose>0 0 0 0 -0 0</pose>
      </inertial>
      <self_collide>0</self_collide>
      <enable_wind>0</enable_wind>
      <kinematic>0</kinematic>
      <visual name='visual'>
        <pose>0 0 0 0 -0 0</pose>
        <geometry>
          <sphere>
            <radius>0.2</radius>
          </sphere>
        </geometry>
        <material>
          <script>
            <uri>file://media/materials/scripts/gazebo.material</uri>
            <name>Gazebo/Grey</name>
          </script>
          <shader type='pixel'/>
        </material>
        <cast_shadows>1</cast_shadows>
        <transparency>0</transparency>
      </visual>
      <collision name='collision'>
        <laser_retro>0</laser_retro>
        <max_contacts>10</max_contacts>
        <pose>0 0 0 0 -0 0</pose>
        <geometry>
          <sphere>
            <radius>0.2</radius>
          </sphere>
        </geometry>
        <surface>
          <friction>
            <ode>
              <mu>1</mu>
              <mu2>1</mu2>
              <fdir1>0 0 0</fdir1>
              <slip1>0</slip1>
              <slip2>0</slip2>
            </ode>
            <torsional>
              <coefficient>1</coefficient>
              <patch_radius>0</patch_radius>
              <surface_radius>0</surface_radius>
              <use_patch_radius>1</use_patch_radius>
              <ode>
                <slip>0</slip>
              </ode>
            </torsional>
          </friction>
          <bounce>
            <restitution_coefficient>0</restitution_coefficient>
            <threshold>1e+06</threshold>
          </bounce>
          <contact>
            <collide_without_contact>0</collide_without_contact>
            <collide_without_contact_bitmask>1</collide_without_contact_bitmask>
            <collide_bitmask>1</collide_bitmask>
            <ode>
              <soft_cfm>0</soft_cfm>
              <soft_erp>0.2</soft_erp>
              <kp>1e+13</kp>
              <kd>1</kd>
              <max_vel>0.01</max_vel>
              <min_depth>0</min_depth>
            </ode>
            <bullet>
              <split_impulse>1</split_impulse>
              <split_impulse_penetration_threshold>-0.01</split_impulse_penetration_threshold>
              <soft_cfm>0</soft_cfm>
              <soft_erp>0.2</soft_erp>
              <kp>1e+13</kp>
              <kd>1</kd>
            </bullet>
          </contact>
        </surface>
      </collision>
    </link>
    <link name='chassis'>
      <pose>-0.151427 0 0.175 0 -0 0</pose>
      <inertial>
        <mass>1.14395</mass>
        <inertia>
          <ixx>0.126164</ixx>
          <ixy>0</ixy>
          <ixz>0</ixz>
          <iyy>0.416519</iyy>
          <iyz>0</iyz>
          <izz>0.481014</izz>
        </inertia>
        <pose>0 0 0 0 -0 0</pose>
      </inertial>
      <self_collide>0</self_collide>
      <enable_wind>0</enable_wind>
      <kinematic>0</kinematic>
      <visual name='visual'>
        <pose>0 0 0 0 -0 0</pose>
        <geometry>
          <box>
            <size>2.01142 1 0.568726</size>
          </box>
        </geometry>
        <material>
          <script>
            <uri>file://media/materials/scripts/gazebo.material</uri>
            <name>Gazebo/Grey</name>
          </script>
          <shader type='pixel'/>
        </material>
        <cast_shadows>1</cast_shadows>
        <transparency>0</transparency>
      </visual>
      <collision name='collision'>
        <laser_retro>0</laser_retro>
        <max_contacts>10</max_contacts>
        <pose>0 0 0 0 -0 0</pose>
        <geometry>
          <box>
            <size>2.01142 1 0.568726</size>
          </box>
        </geometry>
        <surface>
          <friction>
            <ode>
              <mu>1</mu>
              <mu2>1</mu2>
              <fdir1>0 0 0</fdir1>
              <slip1>0</slip1>
              <slip2>0</slip2>
            </ode>
            <torsional>
              <coefficient>1</coefficient>
              <patch_radius>0</patch_radius>
              <surface_radius>0</surface_radius>
              <use_patch_radius>1</use_patch_radius>
              <ode>
                <slip>0</slip>
              </ode>
            </torsional>
          </friction>
          <bounce>
            <restitution_coefficient>0</restitution_coefficient>
            <threshold>1e+06</threshold>
          </bounce>
          <contact>
            <collide_without_contact>0</collide_without_contact>
            <collide_without_contact_bitmask>1</collide_without_contact_bitmask>
            <collide_bitmask>1</collide_bitmask>
            <ode>
              <soft_cfm>0</soft_cfm>
              <soft_erp>0.2</soft_erp>
              <kp>1e+13</kp>
              <kd>1</kd>
              <max_vel>0.01</max_vel>
              <min_depth>0</min_depth>
            </ode>
            <bullet>
              <split_impulse>1</split_impulse>
              <split_impulse_penetration_threshold>-0.01</split_impulse_penetration_threshold>
              <soft_cfm>0</soft_cfm>
              <soft_erp>0.2</soft_erp>
              <kp>1e+13</kp>
              <kd>1</kd>
            </bullet>
          </contact>
        </surface>
      </collision>
    </link>
    <link name='wheel_1'>
      <pose>0.554283 0.625029 -0.025 1.5707 -0 0</pose>
      <inertial>
        <mass>2</mass>
        <inertia>
          <ixx>0.145833</ixx>
          <ixy>0</ixy>
          <ixz>0</ixz>
          <iyy>0.145833</iyy>
          <iyz>0</iyz>
          <izz>0.125</izz>
        </inertia>
        <pose>0 0 0 0 -0 0</pose>
      </inertial>
      <self_collide>0</self_collide>
      <enable_wind>0</enable_wind>
      <kinematic>0</kinematic>
      <visual name='visual'>
        <pose>0 0 0 0 -0 0</pose>
        <geometry>
          <cylinder>
            <radius>0.3</radius>
            <length>0.25</length>
          </cylinder>
        </geometry>
        <material>
          <script>
            <uri>file://media/materials/scripts/gazebo.material</uri>
            <name>Gazebo/Grey</name>
          </script>
          <shader type='pixel'/>
        </material>
        <cast_shadows>1</cast_shadows>
        <transparency>0</transparency>
      </visual>
      <collision name='collision'>
        <laser_retro>0</laser_retro>
        <max_contacts>10</max_contacts>
        <pose>0 0 0 0 -0 0</pose>
        <geometry>
          <cylinder>
            <radius>0.3</radius>
            <length>0.25</length>
          </cylinder>
        </geometry>
        <surface>
          <friction>
            <ode>
              <mu>1</mu>
              <mu2>1</mu2>
              <fdir1>0 0 0</fdir1>
              <slip1>0</slip1>
              <slip2>0</slip2>
            </ode>
            <torsional>
              <coefficient>1</coefficient>
              <patch_radius>0</patch_radius>
              <surface_radius>0</surface_radius>
              <use_patch_radius>1</use_patch_radius>
              <ode>
                <slip>0</slip>
              </ode>
            </torsional>
          </friction>
          <bounce>
            <restitution_coefficient>0</restitution_coefficient>
            <threshold>1e+06</threshold>
          </bounce>
          <contact>
            <collide_without_contact>0</collide_without_contact>
            <collide_without_contact_bitmask>1</collide_without_contact_bitmask>
            <collide_bitmask>1</collide_bitmask>
            <ode>
              <soft_cfm>0</soft_cfm>
              <soft_erp>0.2</soft_erp>
              <kp>1e+13</kp>
              <kd>1</kd>
              <max_vel>0.01</max_vel>
              <min_depth>0</min_depth>
            </ode>
            <bullet>
              <split_impulse>1</split_impulse>
              <split_impulse_penetration_threshold>-0.01</split_impulse_penetration_threshold>
              <soft_cfm>0</soft_cfm>
              <soft_erp>0.2</soft_erp>
              <kp>1e+13</kp>
              <kd>1</kd>
            </bullet>
          </contact>
        </surface>
      </collision>
    </link>
    <link name='wheel_2'>
      <pose>0.554282 -0.625029 -0.025 1.5707 -0 0</pose>
      <inertial>
        <mass>2</mass>
        <inertia>
          <ixx>0.145833</ixx>
          <ixy>0</ixy>
          <ixz>0</ixz>
          <iyy>0.145833</iyy>
          <iyz>0</iyz>
          <izz>0.125</izz>
        </inertia>
        <pose>0 0 0 0 -0 0</pose>
      </inertial>
      <self_collide>0</self_collide>
      <enable_wind>0</enable_wind>
      <kinematic>0</kinematic>
      <visual name='visual'>
        <pose>0 0 0 0 -0 0</pose>
        <geometry>
          <cylinder>
            <radius>0.3</radius>
            <length>0.25</length>
          </cylinder>
        </geometry>
        <material>
          <script>
            <uri>file://media/materials/scripts/gazebo.material</uri>
            <name>Gazebo/Grey</name>
          </script>
          <shader type='pixel'/>
        </material>
        <cast_shadows>1</cast_shadows>
        <transparency>0</transparency>
      </visual>
      <collision name='collision'>
        <laser_retro>0</laser_retro>
        <max_contacts>10</max_contacts>
        <pose>0 0 0 0 -0 0</pose>
        <geometry>
          <cylinder>
            <radius>0.3</radius>
            <length>0.25</length>
          </cylinder>
        </geometry>
        <surface>
          <friction>
            <ode>
              <mu>1</mu>
              <mu2>1</mu2>
              <fdir1>0 0 0</fdir1>
              <slip1>0</slip1>
              <slip2>0</slip2>
            </ode>
            <torsional>
              <coefficient>1</coefficient>
              <patch_radius>0</patch_radius>
              <surface_radius>0</surface_radius>
              <use_patch_radius>1</use_patch_radius>
              <ode>
                <slip>0</slip>
              </ode>
            </torsional>
          </friction>
          <bounce>
            <restitution_coefficient>0</restitution_coefficient>
            <threshold>1e+06</threshold>
          </bounce>
          <contact>
            <collide_without_contact>0</collide_without_contact>
            <collide_without_contact_bitmask>1</collide_without_contact_bitmask>
            <collide_bitmask>1</collide_bitmask>
            <ode>
              <soft_cfm>0</soft_cfm>
              <soft_erp>0.2</soft_erp>
              <kp>1e+13</kp>
              <kd>1</kd>
              <max_vel>0.01</max_vel>
              <min_depth>0</min_depth>
            </ode>
            <bullet>
              <split_impulse>1</split_impulse>
              <split_impulse_penetration_threshold>-0.01</split_impulse_penetration_threshold>
              <soft_cfm>0</soft_cfm>
              <soft_erp>0.2</soft_erp>
              <kp>1e+13</kp>
              <kd>1</kd>
            </bullet>
          </contact>
        </surface>
      </collision>
    </link>
    <model name='depth_camera'>
      <link name='link'>
        <pose>0.05 0.05 0.05 0 -0 0</pose>
        <inertial>
          <mass>0.1</mass>
          <inertia>
            <ixx>0.000166667</ixx>
            <iyy>0.000166667</iyy>
            <izz>0.000166667</izz>
            <ixy>0</ixy>
            <ixz>0</ixz>
            <iyz>0</iyz>
          </inertia>
          <pose>0 0 0 0 -0 0</pose>
        </inertial>
        <collision name='collision'>
          <geometry>
            <box>
              <size>0.1 0.1 0.1</size>
            </box>
          </geometry>
          <max_contacts>10</max_contacts>
          <surface>
            <contact>
              <ode/>
            </contact>
            <bounce/>
            <friction>
              <torsional>
                <ode/>
              </torsional>
              <ode/>
            </friction>
          </surface>
        </collision>
        <visual name='visual'>
          <geometry>
            <box>
              <size>0.1 0.1 0.1</size>
            </box>
          </geometry>
        </visual>
        <sensor name='camera' type='depth'>
          <camera name='depth'>
            <horizontal_fov>1.047</horizontal_fov>
            <image>
              <width>320</width>
              <height>240</height>
            </image>
            <clip>
              <near>0.1</near>
              <far>100</far>
            </clip>
          </camera>
          <always_on>1</always_on>
          <update_rate>30</update_rate>
          <visualize>1</visualize>
        </sensor>
        <self_collide>0</self_collide>
        <enable_wind>0</enable_wind>
        <kinematic>0</kinematic>
      </link>
      <pose>0.569632 -0.03223 0.502056 0 -0 0</pose>
    </model>
    <joint name='chassis_caster_ball' type='ball'>
      <parent>chassis</parent>
      <child>caster</child>
      <pose>0 0 0 0 -0 0</pose>
      <physics>
        <ode>
          <limit>
            <cfm>0</cfm>
            <erp>0.2</erp>
          </limit>
          <suspension>
            <cfm>0</cfm>
            <erp>0.2</erp>
          </suspension>
        </ode>
      </physics>
    </joint>
    <joint name='chassis_depth_camera_link_fixed' type='fixed'>
      <parent>chassis</parent>
      <child>depth_camera::link</child>
      <pose>0 0 0 0 -0 0</pose>
      <physics>
        <ode>
          <limit>
            <cfm>0</cfm>
            <erp>0.2</erp>
          </limit>
          <suspension>
            <cfm>0</cfm>
            <erp>0.2</erp>
          </suspension>
        </ode>
      </physics>
    </joint>
    <joint name='chassis_wheel_1_revolute' type='revolute'>
      <parent>chassis</parent>
      <child>wheel_1</child>
      <pose>0 0 0 0 -0 0</pose>
      <axis>
        <xyz>0 0 1</xyz>
        <limit>
          <lower>-1.79769e+308</lower>
          <upper>1.79769e+308</upper>
          <effort>-1</effort>
          <velocity>-1</velocity>
        </limit>
        <dynamics>
          <spring_reference>0</spring_reference>
          <spring_stiffness>0</spring_stiffness>
          <damping>0</damping>
          <friction>0</friction>
        </dynamics>
      </axis>
      <physics>
        <ode>
          <limit>
            <cfm>0</cfm>
            <erp>0.2</erp>
          </limit>
          <suspension>
            <cfm>0</cfm>
            <erp>0.2</erp>
          </suspension>
        </ode>
      </physics>
    </joint>
    <joint name='chassis_wheel_2_revolute' type='revolute'>
      <parent>chassis</parent>
      <child>wheel_2</child>
      <pose>0 0 0 0 -0 0</pose>
      <axis>
        <xyz>0 0 1</xyz>
        <limit>
          <lower>-1.79769e+308</lower>
          <upper>1.79769e+308</upper>
          <effort>-1</effort>
          <velocity>-1</velocity>
        </limit>
        <dynamics>
          <spring_reference>0</spring_reference>
          <spring_stiffness>0</spring_stiffness>
          <damping>0</damping>
          <friction>0</friction>
        </dynamics>
      </axis>
      <physics>
        <ode>
          <limit>
            <cfm>0</cfm>
            <erp>0.2</erp>
          </limit>
          <suspension>
            <cfm>0</cfm>
            <erp>0.2</erp>
          </suspension>
        </ode>
      </physics>
    </joint>
    <static>1</static>
    <allow_auto_disable>1</allow_auto_disable>
    <plugin name='follower' filename='libFollowerPlugin.so'/>
  </model>
</sdf>
